Workbook
Name UPDATE: 'Data Sheet'!$E$1

Sheet Profit & Loss
A1: ='Data Sheet'!B1 -> ULTRATECH CEMENT LTD | H1: =UPDATE | M1: SCREENER.IN
A3: Narration | B3: ='Data Sheet'!B16 -> 42460 | C3: ='Data Sheet'!C16 -> 42825 | D3: ='Data Sheet'!D16 -> 43190 | E3: ='Data Sheet'!E16 -> 43555 | F3: ='Data Sheet'!F16 -> 43921 | G3: ='Data Sheet'!G16 -> 44286 | H3: ='Data Sheet'!H16 -> 44651 | I3: ='Data Sheet'!I16 -> 45016 | ... K3: ='Data Sheet'!K16 -> 45747 | L3: Trailing | M3: Best Case | N3: Worst Case
A4: Sales | B4: ='Data Sheet'!B17 -> 25153.24 | C4: ='Data Sheet'!C17 -> 25374.94 | D4: ='Data Sheet'!D17 -> 30978.62 | E4: ='Data Sheet'!E17 -> 41462.26 | F4: ='Data Sheet'!F17 -> 42429.89 | G4: ='Data Sheet'!G17 -> 44725.8 | H4: ='Data Sheet'!H17 -> 52598.83 | I4: ='Data Sheet'!I17 -> 63239.98 | ... K4: ='Data Sheet'!K17 -> 75955.13 | L4: =SUM(Quarters!H4:K4) -> 81724.53 | M4: =$K4+M23*K4 -> 85852.073 | N4: =$K4+N23*L4 -> 82162.762
A5: Expenses | B5: =SUM('Data Sheet'!B18,'Data Sheet'!B20:B24, -1*'Data Sheet'!B19) -> 20252.27 | C5: =SUM('Data Sheet'!C18,'Data Sheet'!C20:C24, -1*'Data Sheet'!C19) -> 20162.5 | D5: =SUM('Data Sheet'!D18,'Data Sheet'!D20:D24, -1*'Data Sheet'!D19) -> 24833.59 | E5: =SUM('Data Sheet'!E18,'Data Sheet'!E20:E24, -1*'Data Sheet'!E19) -> 34115.32 | F5: =SUM('Data Sheet'!F18,'Data Sheet'!F20:F24, -1*'Data Sheet'!F19) -> 33183.92 | G5: =SUM('Data Sheet'!G18,'Data Sheet'!G20:G24, -1*'Data Sheet'!G19) -> 33157.89 | H5: =SUM('Data Sheet'!H18,'Data Sheet'!H20:H24, -1*'Data Sheet'!H19) -> 41084.48 | I5: =SUM('Data Sheet'!I18,'Data Sheet'!I20:I24, -1*'Data Sheet'!I19) -> 52620.13 | ... K5: =SUM('Data Sheet'!K18,'Data Sheet'!K20:K24, -1*'Data Sheet'!K19) -> 63158.25 | L5: =SUM(Quarters!H5:K5) -> 66728.69 | M5: =M4-M6 -> 70098.86 | N5: =N4-N6 -> 67930.057
A6: Operating Profit | B6: =B4-B5 -> 4900.97 | C6: =C4-C5 -> 5212.44 | D6: =D4-D5 -> 6145.03 | E6: =E4-E5 -> 7346.94 | F6: =F4-F5 -> 9245.97 | G6: =G4-G5 -> 11567.91 | H6: =H4-H5 -> 11514.35 | I6: =I4-I5 -> 10619.85 | ... K6: =K4-K5 -> 12796.88 | L6: =SUM(Quarters!H6:K6) -> 14995.84 | M6: =M4*M24 -> 15753.213 | N6: =N4*N24 -> 14232.705
A7: Other Income | B7: ='Data Sheet'!B25 -> 463.81 | C7: ='Data Sheet'!C25 -> 648.12 | D7: ='Data Sheet'!D25 -> 241.97 | E7: ='Data Sheet'!E25 -> 350.1 | F7: ='Data Sheet'!F25 -> 651.06 | G7: ='Data Sheet'!G25 -> 618.52 | H7: ='Data Sheet'!H25 -> 669.43 | I7: ='Data Sheet'!I25 -> 507.11 | ... K7: ='Data Sheet'!K25 -> 396.74 | L7: =SUM(Quarters!H7:K7) -> 656.09 | M7: 0 | N7: 0
A8: Depreciation | B8: ='Data Sheet'!B26 -> 1377.17 | C8: ='Data Sheet'!C26 -> 1348.41 | D8: ='Data Sheet'!D26 -> 1847.93 | E8: ='Data Sheet'!E26 -> 2450.73 | F8: ='Data Sheet'!F26 -> 2722.66 | G8: ='Data Sheet'!G26 -> 2700.23 | H8: ='Data Sheet'!H26 -> 2714.75 | I8: ='Data Sheet'!I26 -> 2887.99 | ... K8: ='Data Sheet'!K26 -> 4014.95 | L8: =SUM(Quarters!H8:K8) -> 4371.81 | M8: =+$L8 -> 4371.81 | N8: =+$L8 -> 4371.81
A9: Interest | B9: ='Data Sheet'!B27 -> 566.3 | C9: ='Data Sheet'!C27 -> 640.1 | D9: ='Data Sheet'!D27 -> 1237.6 | E9: ='Data Sheet'!E27 -> 1777.86 | F9: ='Data Sheet'!F27 -> 1991.65 | G9: ='Data Sheet'!G27 -> 1485.65 | H9: ='Data Sheet'!H27 -> 944.71 | I9: ='Data Sheet'!I27 -> 822.72 | ... K9: ='Data Sheet'!K27 -> 1650.54 | L9: =SUM(Quarters!H9:K9) -> 1824.38 | M9: =+$L9 -> 1824.38 | N9: =+$L9 -> 1824.38
A10: Profit before tax | B10: ='Data Sheet'!B28 -> 3421.31 | C10: ='Data Sheet'!C28 -> 3872.05 | D10: ='Data Sheet'!D28 -> 3301.47 | E10: ='Data Sheet'!E28 -> 3468.45 | F10: ='Data Sheet'!F28 -> 5182.72 | G10: ='Data Sheet'!G28 -> 8000.55 | H10: ='Data Sheet'!H28 -> 8524.32 | I10: ='Data Sheet'!I28 -> 7416.25 | ... K10: ='Data Sheet'!K28 -> 7528.13 | L10: =SUM(Quarters!H10:K10) -> 9455.74 | M10: =M6+M7-SUM(M8:M9) -> 9557.0233 | N10: =N6+N7-SUM(N8:N9) -> 8036.5149
A11: Tax | B11: ='Data Sheet'!B29 -> 941.69 | C11: ='Data Sheet'!C29 -> 1158.54 | D11: ='Data Sheet'!D29 -> 1077.01 | E11: ='Data Sheet'!E29 -> 1068.07 | F11: ='Data Sheet'!F29 -> -568.16 | G11: ='Data Sheet'!G29 -> 2538.7 | H11: ='Data Sheet'!H29 -> 1190.06 | I11: ='Data Sheet'!I29 -> 2342.85 | ... K11: ='Data Sheet'!K29 -> 1488.49 | L11: =SUM(Quarters!H11:K11) -> 2158.62 | M11: =IF($L10>0,$L11/$L10,0) -> 0.22828673 | N11: =IF($L10>0,$L11/$L10,0) -> 0.22828673
A12: Net profit | B12: ='Data Sheet'!B30 -> 2478.04 | C12: ='Data Sheet'!C30 -> 2714.92 | D12: ='Data Sheet'!D30 -> 2222.17 | E12: ='Data Sheet'!E30 -> 2403.51 | F12: ='Data Sheet'!F30 -> 5755.26 | G12: ='Data Sheet'!G30 -> 5463.1 | H12: ='Data Sheet'!H30 -> 7344.31 | I12: ='Data Sheet'!I30 -> 5063.96 | ... K12: ='Data Sheet'!K30 -> 6039.11 | L12: =SUM(Quarters!H12:K12) -> 7298.95 | M12: =M10-M11*M10 -> 7375.2817 | N12: =N10-N11*N10 -> 6201.8852
A13: EPS | B13: =IF('Data Sheet'!B93>0,B12/'Data Sheet'!B93,0) -> 90.30758 | C13: =IF('Data Sheet'!C93>0,C12/'Data Sheet'!C93,0) -> 98.904189 | D13: =IF('Data Sheet'!D93>0,D12/'Data Sheet'!D93,0) -> 80.923889 | E13: =IF('Data Sheet'!E93>0,E12/'Data Sheet'!E93,0) -> 87.527677 | F13: =IF('Data Sheet'!F93>0,F12/'Data Sheet'!F93,0) -> 199.41996 | G13: =IF('Data Sheet'!G93>0,G12/'Data Sheet'!G93,0) -> 189.23104 | H13: =IF('Data Sheet'!H93>0,H12/'Data Sheet'!H93,0) -> 254.39245 | I13: =IF('Data Sheet'!I93>0,I12/'Data Sheet'!I93,0) -> 175.40561 | ... K13: =IF('Data Sheet'!K93>0,K12/'Data Sheet'!K93,0) -> 204.92399 | L13: =IF('Data Sheet'!$B6>0,'Profit & Loss'!L12/'Data Sheet'!$B6,0) -> 247.72486 | M13: =IF('Data Sheet'!$B6>0,'Profit & Loss'!M12/'Data Sheet'!$B6,0) -> 250.31554 | N13: =IF('Data Sheet'!$B6>0,'Profit & Loss'!N12/'Data Sheet'!$B6,0) -> 210.4907
A14: Price to earning | B14: =IF(B15>0,B15/B13,"") -> 35.752813 | C14: =IF(C15>0,C15/C13,"") -> 40.288991 | D14: =IF(D15>0,D15/D13,"") -> 48.811297 | E14: =IF(E15>0,E15/E13,"") -> 45.680979 | F14: =IF(F15>0,F15/F13,"") -> 16.271441 | G14: =IF(G15>0,G15/G13,"") -> 35.607003 | H14: =IF(H15>0,H15/H13,"") -> 25.953207 | I14: =IF(I15>0,I15/I13,"") -> 43.454425 | ... K14: =IF(K15>0,K15/K13,"") -> 56.164971 | L14: =IF(L13>0,L15/L13,0) -> 47.431655 | M14: =M25 -> 47.431655 | N14: =N25 -> 38.842908
A15: Price | B15: ='Data Sheet'!B90 -> 3228.75 | C15: ='Data Sheet'!C90 -> 3984.75 | D15: ='Data Sheet'!D90 -> 3950 | E15: ='Data Sheet'!E90 -> 3998.35 | F15: ='Data Sheet'!F90 -> 3244.85 | G15: ='Data Sheet'!G90 -> 6737.95 | H15: ='Data Sheet'!H90 -> 6602.3 | I15: ='Data Sheet'!I90 -> 7622.15 | ... K15: ='Data Sheet'!K90 -> 11509.55 | L15: ='Data Sheet'!B8 -> 11750 | M15: =M13*M14 -> 11872.88 | N15: =N13*N14 -> 8176.0709
A17: RATIOS:
A18: Dividend Payout | B18: =IF('Data Sheet'!B30>0, 'Data Sheet'!B31/'Data Sheet'!B30, 0) -> 0.10520815 | C18: =IF('Data Sheet'!C30>0, 'Data Sheet'!C31/'Data Sheet'!C30, 0) -> 0.10111163 | D18: =IF('Data Sheet'!D30>0, 'Data Sheet'!D31/'Data Sheet'!D30, 0) -> 0.12975605 | E18: =IF('Data Sheet'!E30>0, 'Data Sheet'!E31/'Data Sheet'!E30, 0) -> 0.13140782 | F18: =IF('Data Sheet'!F30>0, 'Data Sheet'!F31/'Data Sheet'!F30, 0) -> 0.065196012 | G18: =IF('Data Sheet'!G30>0, 'Data Sheet'!G31/'Data Sheet'!G30, 0) -> 0.1954934 | H18: =IF('Data Sheet'!H30>0, 'Data Sheet'!H31/'Data Sheet'!H30, 0) -> 0.14936053 | I18: =IF('Data Sheet'!I30>0, 'Data Sheet'!I31/'Data Sheet'!I30, 0) -> 0.21663283 | ... K18: =IF('Data Sheet'!K30>0, 'Data Sheet'!K31/'Data Sheet'!K30, 0) -> 0.37816334
A19: OPM | B19: =IF(B6>0,B6/B4,0) -> 0.19484448 | C19: =IF(C6>0,C6/C4,0) -> 0.20541684 | D19: =IF(D6>0,D6/D4,0) -> 0.19836358 | E19: =IF(E6>0,E6/E4,0) -> 0.17719584 | F19: =IF(F6>0,F6/F4,0) -> 0.21791171 | G19: =IF(G6>0,G6/G4,0) -> 0.25864065 | H19: =IF(H6>0,H6/H4,0) -> 0.21890886 | I19: =IF(I6>0,I6/I4,0) -> 0.16792937 | ... L19: =IF(L6>0,L6/L4,0) -> 0.18349252
G22: TRENDS: | H22: 10 YEARS | I22: 7 YEARS | J22: 5 YEARS | K22: 3 YEARS | L22: RECENT | M22: BEST | N22: WORST
G23: Sales Growth | H23: =IF(B4=0,"",POWER($K4/B4,1/9)-1) -> 0.13065275 | I23: =IF(D4=0,"",POWER($K4/D4,1/7)-1) -> 0.13669029 | J23: =IF(F4=0,"",POWER($K4/F4,1/5)-1) -> 0.12351026 | K23: =IF(H4=0,"",POWER($K4/H4, 1/3)-1) -> 0.13029987 | L23: =IF(ISERROR(MAX(IF(J4=0,"",(K4-J4)/J4),IF(K4=0,"",(L4-K4)/K4))),"",MAX(IF(J4=0,"",(K4-J4)/J4),IF(K4=0,"",(L4-K4)/K4))) -> 0.075958003 | M23: =MAX(K23:L23) -> 0.13029987 | N23: =MIN(H23:L23) -> 0.075958003
G24: OPM | H24: =IF(SUM(B4:$K$4)=0,"",SUMPRODUCT(B19:$K$19,B4:$K$4)/SUM(B4:$K$4)) -> 0.19527001 | I24: =IF(SUM(E4:$K$4)=0,"",SUMPRODUCT(E19:$K$19,E4:$K$4)/SUM(E4:$K$4)) -> 0.1943945 | J24: =IF(SUM(G4:$K$4)=0,"",SUMPRODUCT(G19:$K$19,G4:$K$4)/SUM(G4:$K$4)) -> 0.1934683 | K24: =IF(SUM(I4:$K$4)=0, "", SUMPRODUCT(I19:$K$19,I4:$K$4)/SUM(I4:$K$4)) -> 0.17322574 | L24: =L19 -> 0.18349252 | M24: =MAX(K24:L24) -> 0.18349252 | N24: =MIN(H24:L24) -> 0.17322574
G25: Price to Earning | H25: =IF(ISERROR(AVERAGEIF(B14:$L14,">0")),"",AVERAGEIF(B14:$L14,">0")) -> 39.599669 | I25: =IF(ISERROR(AVERAGEIF(E14:$L14,">0")),"",AVERAGEIF(E14:$L14,">0")) -> 38.842908 | J25: =IF(ISERROR(AVERAGEIF(G14:$L14,">0")),"",AVERAGEIF(G14:$L14,">0")) -> 41.46514 | K25: =IF(ISERROR(AVERAGEIF(I14:$L14,">0")),"",AVERAGEIF(I14:$L14,">0")) -> 46.807658 | L25: =L14 -> 47.431655 | M25: =MAX(K25:L25) -> 47.431655 | N25: =MIN(H25:L25) -> 38.842908

Sheet Quarters
A1: ='Profit & Loss'!A1 -> ULTRATECH CEMENT LTD | E1: =UPDATE | J1: SCREENER.IN
A3: Narration | B3: ='Data Sheet'!B41 -> 45107 | C3: ='Data Sheet'!C41 -> 45199 | D3: ='Data Sheet'!D41 -> 45291 | E3: ='Data Sheet'!E41 -> 45382 | F3: ='Data Sheet'!F41 -> 45473 | G3: ='Data Sheet'!G41 -> 45565 | H3: ='Data Sheet'!H41 -> 45657 | I3: ='Data Sheet'!I41 -> 45747 | ... K3: ='Data Sheet'!K41 -> 45930
A4: Sales | B4: ='Data Sheet'!B42 -> 17737.1 | C4: ='Data Sheet'!C42 -> 16012.13 | D4: ='Data Sheet'!D42 -> 16739.97 | E4: ='Data Sheet'!E42 -> 20418.94 | F4: ='Data Sheet'!F42 -> 18818.56 | G4: ='Data Sheet'!G42 -> 16294.42 | H4: ='Data Sheet'!H42 -> 17778.83 | I4: ='Data Sheet'!I42 -> 23063.32 | ... K4: ='Data Sheet'!K42 -> 19606.93
A5: Expenses | B5: ='Data Sheet'!B43 -> 14687.92 | C5: ='Data Sheet'!C43 -> 13461.24 | D5: ='Data Sheet'!D43 -> 13485.4 | E5: ='Data Sheet'!E43 -> 16305.02 | F5: ='Data Sheet'!F43 -> 15801.46 | G5: ='Data Sheet'!G43 -> 14268.68 | H5: ='Data Sheet'!H43 -> 14885.35 | I5: ='Data Sheet'!I43 -> 18455.65 | ... K5: ='Data Sheet'!K43 -> 16518.27
A6: Operating Profit | B6: ='Data Sheet'!B50 -> 3049.18 | C6: ='Data Sheet'!C50 -> 2550.89 | D6: ='Data Sheet'!D50 -> 3254.57 | E6: ='Data Sheet'!E50 -> 4113.92 | F6: ='Data Sheet'!F50 -> 3017.1 | G6: ='Data Sheet'!G50 -> 2025.74 | H6: ='Data Sheet'!H50 -> 2893.48 | I6: ='Data Sheet'!I50 -> 4607.67 | ... K6: ='Data Sheet'!K50 -> 3088.66
A7: Other Income | B7: ='Data Sheet'!B44 -> 177.43 | C7: ='Data Sheet'!C44 -> 170.62 | D7: ='Data Sheet'!D44 -> 146.24 | E7: ='Data Sheet'!E44 -> 72.67 | F7: ='Data Sheet'!F44 -> 83.31 | G7: ='Data Sheet'!G44 -> 226.22 | H7: ='Data Sheet'!H44 -> 247.32 | I7: ='Data Sheet'!I44 -> 92.78 | ... K7: ='Data Sheet'!K44 -> 174.14
A8: Depreciation | B8: ='Data Sheet'!B45 -> 749.07 | C8: ='Data Sheet'!C45 -> 797.83 | D8: ='Data Sheet'!D45 -> 783.48 | E8: ='Data Sheet'!E45 -> 814.92 | F8: ='Data Sheet'!F45 -> 917.93 | G8: ='Data Sheet'!G45 -> 979.67 | H8: ='Data Sheet'!H45 -> 992.78 | I8: ='Data Sheet'!I45 -> 1124.57 | ... K8: ='Data Sheet'!K45 -> 1147.68
A9: Interest | B9: ='Data Sheet'!B46 -> 210.75 | C9: ='Data Sheet'!C46 -> 233.94 | D9: ='Data Sheet'!D46 -> 262.16 | E9: ='Data Sheet'!E46 -> 261.15 | F9: ='Data Sheet'!F46 -> 325.76 | G9: ='Data Sheet'!G46 -> 392.99 | H9: ='Data Sheet'!H46 -> 456.75 | I9: ='Data Sheet'!I46 -> 475.04 | ... K9: ='Data Sheet'!K46 -> 459.29
A10: Profit before tax | B10: ='Data Sheet'!B47 -> 2266.79 | C10: ='Data Sheet'!C47 -> 1689.74 | D10: ='Data Sheet'!D47 -> 2355.17 | E10: ='Data Sheet'!E47 -> 3110.52 | F10: ='Data Sheet'!F47 -> 1856.72 | G10: ='Data Sheet'!G47 -> 879.3 | H10: ='Data Sheet'!H47 -> 1691.27 | I10: ='Data Sheet'!I47 -> 3100.84 | ... K10: ='Data Sheet'!K47 -> 1655.83
A11: Tax | B11: ='Data Sheet'!B48 -> 576.57 | C11: ='Data Sheet'!C48 -> 409.36 | D11: ='Data Sheet'!D48 -> 580.39 | E11: ='Data Sheet'!E48 -> 851.94 | F11: ='Data Sheet'!F48 -> 363.27 | G11: ='Data Sheet'!G48 -> 171.34 | H11: ='Data Sheet'!H48 -> 327.83 | I11: ='Data Sheet'!I48 -> 626.05 | ... K11: ='Data Sheet'!K48 -> 417.85
A12: Net profit | B12: ='Data Sheet'!B49 -> 1688.45 | C12: ='Data Sheet'!C49 -> 1281.45 | D12: ='Data Sheet'!D49 -> 1776.98 | E12: ='Data Sheet'!E49 -> 2258.12 | F12: ='Data Sheet'!F49 -> 1494.82 | G12: ='Data Sheet'!G49 -> 702.82 | H12: ='Data Sheet'!H49 -> 1359.43 | I12: ='Data Sheet'!I49 -> 2482.04 | ... K12: ='Data Sheet'!K49 -> 1231.58
A14: OPM | B14: =IF(B4>0,B6/B4,"") -> 0.17190973 | C14: =IF(C4>0,C6/C4,"") -> 0.15930985 | D14: =IF(D4>0,D6/D4,"") -> 0.19441911 | E14: =IF(E4>0,E6/E4,"") -> 0.20147569 | F14: =IF(F4>0,F6/F4,"") -> 0.16032576 | G14: =IF(G4>0,G6/G4,"") -> 0.12432109 | H14: =IF(H4>0,H6/H4,"") -> 0.16274862 | I14: =IF(I4>0,I6/I4,"") -> 0.19978347 | ... K14: =IF(K4>0,K6/K4,"") -> 0.157529

Sheet Balance Sheet
A1: ='Profit & Loss'!A1 -> ULTRATECH CEMENT LTD | E1: =UPDATE | J1: SCREENER.IN
A3: Narration | B3: ='Data Sheet'!B56 -> 42460 | C3: ='Data Sheet'!C56 -> 42825 | D3: ='Data Sheet'!D56 -> 43190 | E3: ='Data Sheet'!E56 -> 43555 | F3: ='Data Sheet'!F56 -> 43921 | G3: ='Data Sheet'!G56 -> 44286 | H3: ='Data Sheet'!H56 -> 44651 | I3: ='Data Sheet'!I56 -> 45016 | ... K3: ='Data Sheet'!K56 -> 45747
A4: Equity Share Capital | B4: ='Data Sheet'!B57 -> 274.43 | C4: ='Data Sheet'!C57 -> 274.51 | D4: ='Data Sheet'!D57 -> 274.61 | E4: ='Data Sheet'!E57 -> 274.64 | F4: ='Data Sheet'!F57 -> 288.63 | G4: ='Data Sheet'!G57 -> 288.65 | H4: ='Data Sheet'!H57 -> 288.67 | I4: ='Data Sheet'!I57 -> 288.69 | ... K4: ='Data Sheet'!K57 -> 294.68
A5: Reserves | B5: ='Data Sheet'!B58 -> 21671.2 | C5: ='Data Sheet'!C58 -> 24117.38 | D5: ='Data Sheet'!D58 -> 26106.55 | E5: ='Data Sheet'!E58 -> 33476.01 | F5: ='Data Sheet'!F58 -> 38755.13 | G5: ='Data Sheet'!G58 -> 43886.03 | H5: ='Data Sheet'!H58 -> 50146.6 | I5: ='Data Sheet'!I58 -> 54035.85 | ... K5: ='Data Sheet'!K58 -> 70412.09
A6: Borrowings | B6: ='Data Sheet'!B59 -> 10615.99 | C6: ='Data Sheet'!C59 -> 8474.49 | D6: ='Data Sheet'!D59 -> 19480.22 | E6: ='Data Sheet'!E59 -> 25337 | F6: ='Data Sheet'!F59 -> 23018.96 | G6: ='Data Sheet'!G59 -> 21719.39 | H6: ='Data Sheet'!H59 -> 11298.8 | I6: ='Data Sheet'!I59 -> 11057.74 | ... K6: ='Data Sheet'!K59 -> 24102.18
A7: Other Liabilities | B7: ='Data Sheet'!B60 -> 8631.49 | C7: ='Data Sheet'!C60 -> 9342.73 | D7: ='Data Sheet'!D60 -> 11279.71 | E7: ='Data Sheet'!E60 -> 17437.72 | F7: ='Data Sheet'!F60 -> 17151.09 | G7: ='Data Sheet'!G60 -> 20282.28 | H7: ='Data Sheet'!H60 -> 22077.37 | I7: ='Data Sheet'!I60 -> 25998.12 | ... K7: ='Data Sheet'!K60 -> 38823.11
A8: Total | B8: ='Data Sheet'!B61 -> 41193.11 | C8: ='Data Sheet'!C61 -> 42209.11 | D8: ='Data Sheet'!D61 -> 57141.09 | E8: ='Data Sheet'!E61 -> 76525.37 | F8: ='Data Sheet'!F61 -> 79213.81 | G8: ='Data Sheet'!G61 -> 86176.35 | H8: ='Data Sheet'!H61 -> 83811.44 | I8: ='Data Sheet'!I61 -> 91380.4 | ... K8: ='Data Sheet'!K61 -> 133632.06
A10: Net Block | B10: ='Data Sheet'!B62 -> 25309.42 | C10: ='Data Sheet'!C62 -> 25903.75 | D10: ='Data Sheet'!D62 -> 39715.3 | E10: ='Data Sheet'!E62 -> 56644.62 | F10: ='Data Sheet'!F62 -> 57150.96 | G10: ='Data Sheet'!G62 -> 55411.61 | H10: ='Data Sheet'!H62 -> 55487.57 | I10: ='Data Sheet'!I62 -> 59579 | ... K10: ='Data Sheet'!K62 -> 94564.22
A11: Capital Work in Progress | B11: ='Data Sheet'!B63 -> 1469.09 | C11: ='Data Sheet'!C63 -> 921.48 | D11: ='Data Sheet'!D63 -> 1511.21 | E11: ='Data Sheet'!E63 -> 1153.32 | F11: ='Data Sheet'!F63 -> 919.59 | G11: ='Data Sheet'!G63 -> 1686.68 | H11: ='Data Sheet'!H63 -> 4784.67 | I11: ='Data Sheet'!I63 -> 4040.39 | ... K11: ='Data Sheet'!K63 -> 6234.19
A12: Investments | B12: ='Data Sheet'!B64 -> 5095.18 | C12: ='Data Sheet'!C64 -> 6690.51 | D12: ='Data Sheet'!D64 -> 5446.9 | E12: ='Data Sheet'!E64 -> 2921.33 | F12: ='Data Sheet'!F64 -> 5928.69 | G12: ='Data Sheet'!G64 -> 12178.11 | H12: ='Data Sheet'!H64 -> 6335.77 | I12: ='Data Sheet'!I64 -> 7296.95 | ... K12: ='Data Sheet'!K64 -> 5156.47
A13: Other Assets | B13: ='Data Sheet'!B65 -> 9319.42 | C13: ='Data Sheet'!C65 -> 8693.37 | D13: ='Data Sheet'!D65 -> 10467.68 | E13: ='Data Sheet'!E65 -> 15806.1 | F13: ='Data Sheet'!F65 -> 15214.57 | G13: ='Data Sheet'!G65 -> 16899.95 | H13: ='Data Sheet'!H65 -> 17203.43 | I13: ='Data Sheet'!I65 -> 20464.06 | ... K13: ='Data Sheet'!K65 -> 27677.18
A14: Total | B14: ='Data Sheet'!B66 -> 41193.11 | C14: ='Data Sheet'!C66 -> 42209.11 | D14: ='Data Sheet'!D66 -> 57141.09 | E14: ='Data Sheet'!E66 -> 76525.37 | F14: ='Data Sheet'!F66 -> 79213.81 | G14: ='Data Sheet'!G66 -> 86176.35 | H14: ='Data Sheet'!H66 -> 83811.44 | I14: ='Data Sheet'!I66 -> 91380.4 | ... K14: ='Data Sheet'!K66 -> 133632.06
A16: Working Capital | B16: =B13-B7 -> 687.93 | C16: =C13-C7 -> -649.36 | D16: =D13-D7 -> -812.03 | E16: =E13-E7 -> -1631.62 | F16: =F13-F7 -> -1936.52 | G16: =G13-G7 -> -3382.33 | H16: =H13-H7 -> -4873.94 | I16: =I13-I7 -> -5534.06 | ... K16: =K13-K7 -> -11145.93
A17: Debtors | B17: ='Data Sheet'!B67 -> 1928.21 | C17: ='Data Sheet'!C67 -> 1757.09 | D17: ='Data Sheet'!D67 -> 2220.63 | E17: ='Data Sheet'!E67 -> 2787.03 | F17: ='Data Sheet'!F67 -> 2383.22 | G17: ='Data Sheet'!G67 -> 2571.73 | H17: ='Data Sheet'!H67 -> 3071.61 | I17: ='Data Sheet'!I67 -> 3867.02 | ... K17: ='Data Sheet'!K67 -> 5890.25
A18: Inventory | B18: ='Data Sheet'!B68 -> 2454.58 | C18: ='Data Sheet'!C68 -> 2400.64 | D18: ='Data Sheet'!D68 -> 3267.59 | E18: ='Data Sheet'!E68 -> 4098.96 | F18: ='Data Sheet'!F68 -> 4183.35 | G18: ='Data Sheet'!G68 -> 4017.97 | H18: ='Data Sheet'!H68 -> 5595.58 | I18: ='Data Sheet'!I68 -> 6611.83 | ... K18: ='Data Sheet'!K68 -> 9562.98
A20: Debtor Days | B20: =IF('Profit & Loss'!B4>0,'Balance Sheet'!B17/('Profit & Loss'!B4/365),0) -> 27.980358 | C20: =IF('Profit & Loss'!C4>0,'Balance Sheet'!C17/('Profit & Loss'!C4/365),0) -> 25.274458 | D20: =IF('Profit & Loss'!D4>0,'Balance Sheet'!D17/('Profit & Loss'!D4/365),0) -> 26.164172 | E20: =IF('Profit & Loss'!E4>0,'Balance Sheet'!E17/('Profit & Loss'!E4/365),0) -> 24.534744 | F20: =IF('Profit & Loss'!F4>0,'Balance Sheet'!F17/('Profit & Loss'!F4/365),0) -> 20.501474 | G20: =IF('Profit & Loss'!G4>0,'Balance Sheet'!G17/('Profit & Loss'!G4/365),0) -> 20.987471 | H20: =IF('Profit & Loss'!H4>0,'Balance Sheet'!H17/('Profit & Loss'!H4/365),0) -> 21.314878 | I20: =IF('Profit & Loss'!I4>0,'Balance Sheet'!I17/('Profit & Loss'!I4/365),0) -> 22.319145 | ... K20: =IF('Profit & Loss'!K4>0,'Balance Sheet'!K17/('Profit & Loss'!K4/365),0) -> 28.305412
A21: Inventory Turnover | B21: =IF('Balance Sheet'!B18>0,'Profit & Loss'!B4/'Balance Sheet'!B18,0) -> 10.247472 | C21: =IF('Balance Sheet'!C18>0,'Profit & Loss'!C4/'Balance Sheet'!C18,0) -> 10.570073 | D21: =IF('Balance Sheet'!D18>0,'Profit & Loss'!D4/'Balance Sheet'!D18,0) -> 9.4805713 | E21: =IF('Balance Sheet'!E18>0,'Profit & Loss'!E4/'Balance Sheet'!E18,0) -> 10.115312 | F21: =IF('Balance Sheet'!F18>0,'Profit & Loss'!F4/'Balance Sheet'!F18,0) -> 10.142563 | G21: =IF('Balance Sheet'!G18>0,'Profit & Loss'!G4/'Balance Sheet'!G18,0) -> 11.131442 | H21: =IF('Balance Sheet'!H18>0,'Profit & Loss'!H4/'Balance Sheet'!H18,0) -> 9.4000676 | I21: =IF('Balance Sheet'!I18>0,'Profit & Loss'!I4/'Balance Sheet'!I18,0) -> 9.5646712 | ... K21: =IF('Balance Sheet'!K18>0,'Profit & Loss'!K4/'Balance Sheet'!K18,0) -> 7.9426214
A23: Return on Equity | B23: =IF(SUM('Balance Sheet'!B4:B5)>0,'Profit & Loss'!B12/SUM('Balance Sheet'!B4:B5),"") -> 0.11291724 | C23: =IF(SUM('Balance Sheet'!C4:C5)>0,'Profit & Loss'!C12/SUM('Balance Sheet'!C4:C5),"") -> 0.11130421 | D23: =IF(SUM('Balance Sheet'!D4:D5)>0,'Profit & Loss'!D12/SUM('Balance Sheet'!D4:D5),"") -> 0.084233218 | E23: =IF(SUM('Balance Sheet'!E4:E5)>0,'Profit & Loss'!E12/SUM('Balance Sheet'!E4:E5),"") -> 0.07121374 | F23: =IF(SUM('Balance Sheet'!F4:F5)>0,'Profit & Loss'!F12/SUM('Balance Sheet'!F4:F5),"") -> 0.14740537 | G23: =IF(SUM('Balance Sheet'!G4:G5)>0,'Profit & Loss'!G12/SUM('Balance Sheet'!G4:G5),"") -> 0.12367039 | H23: =IF(SUM('Balance Sheet'!H4:H5)>0,'Profit & Loss'!H12/SUM('Balance Sheet'!H4:H5),"") -> 0.14561853 | I23: =IF(SUM('Balance Sheet'!I4:I5)>0,'Profit & Loss'!I12/SUM('Balance Sheet'!I4:I5),"") -> 0.093216804 | ... K23: =IF(SUM('Balance Sheet'!K4:K5)>0,'Profit & Loss'!K12/SUM('Balance Sheet'!K4:K5),"") -> 0.085410633
A24: Return on Capital Emp | C24: =IF((B4+B5+B6+C4+C5+C6)>0,('Profit & Loss'!C10+'Profit & Loss'!C9)*2/(B4+B5+B6+C4+C5+C6),"") -> 0.13792719 | D24: =IF((C4+C5+C6+D4+D5+D6)>0,('Profit & Loss'!D10+'Profit & Loss'!D9)*2/(C4+C5+C6+D4+D5+D6),"") -> 0.11531053 | E24: =IF((D4+D5+D6+E4+E5+E6)>0,('Profit & Loss'!E10+'Profit & Loss'!E9)*2/(D4+D5+D6+E4+E5+E6),"") -> 0.099978247 | F24: =IF((E4+E5+E6+F4+F5+F6)>0,('Profit & Loss'!F10+'Profit & Loss'!F9)*2/(E4+E5+E6+F4+F5+F6),"") -> 0.11843744 | G24: =IF((F4+F5+F6+G4+G5+G6)>0,('Profit & Loss'!G10+'Profit & Loss'!G9)*2/(F4+F5+F6+G4+G5+G6),"") -> 0.14827193 | H24: =IF((G4+G5+G6+H4+H5+H6)>0,('Profit & Loss'!H10+'Profit & Loss'!H9)*2/(G4+G5+G6+H4+H5+H6),"") -> 0.14838467 | I24: =IF((H4+H5+H6+I4+I5+I6)>0,('Profit & Loss'!I10+'Profit & Loss'!I9)*2/(H4+H5+H6+I4+I5+I6),"") -> 0.1296288 | J24: =IF((I4+I5+I6+J4+J5+J6)>0,('Profit & Loss'!J10+'Profit & Loss'!J9)*2/(I4+I5+I6+J4+J5+J6),"") -> 0.15166797 | K24: =IF((J4+J5+J6+K4+K5+K6)>0,('Profit & Loss'!K10+'Profit & Loss'!K9)*2/(J4+J5+J6+K4+K5+K6),"") -> 0.11029445

Sheet Cash Flow
A1: ='Balance Sheet'!A1 -> ULTRATECH CEMENT LTD | E1: =UPDATE | J1: SCREENER.IN
A3: Narration | B3: ='Data Sheet'!B81 -> 42460 | C3: ='Data Sheet'!C81 -> 42825 | D3: ='Data Sheet'!D81 -> 43190 | E3: ='Data Sheet'!E81 -> 43555 | F3: ='Data Sheet'!F81 -> 43921 | G3: ='Data Sheet'!G81 -> 44286 | H3: ='Data Sheet'!H81 -> 44651 | I3: ='Data Sheet'!I81 -> 45016 | ... K3: ='Data Sheet'!K81 -> 45747
A4: Cash from Operating Activity | B4: ='Data Sheet'!B82 -> 4525.51 | C4: ='Data Sheet'!C82 -> 5005.02 | D4: ='Data Sheet'!D82 -> 3887.72 | E4: ='Data Sheet'!E82 -> 5956.11 | F4: ='Data Sheet'!F82 -> 8972.43 | G4: ='Data Sheet'!G82 -> 12500.43 | H4: ='Data Sheet'!H82 -> 9283.24 | I4: ='Data Sheet'!I82 -> 9068.51 | ... K4: ='Data Sheet'!K82 -> 10673.43
A5: Cash from Investing Activity | B5: ='Data Sheet'!B83 -> -3673.35 | C5: ='Data Sheet'!C83 -> -2501.44 | D5: ='Data Sheet'!D83 -> 1865.72 | E5: ='Data Sheet'!E83 -> 1165.18 | F5: ='Data Sheet'!F83 -> -4191.95 | G5: ='Data Sheet'!G83 -> -8856.15 | H5: ='Data Sheet'!H83 -> 2256.54 | I5: ='Data Sheet'!I83 -> -7187.68 | ... K5: ='Data Sheet'!K83 -> -15835.56
A6: Cash from Financing Activity | B6: ='Data Sheet'!B84 -> -844.02 | C6: ='Data Sheet'!C84 -> -2534.98 | D6: ='Data Sheet'!D84 -> -5735.05 | E6: ='Data Sheet'!E84 -> -6757.24 | F6: ='Data Sheet'!F84 -> -5075.88 | G6: ='Data Sheet'!G84 -> -4356.47 | H6: ='Data Sheet'!H84 -> -12497.93 | I6: ='Data Sheet'!I84 -> -1631 | ... K6: ='Data Sheet'!K84 -> 5075.76
A7: Net Cash Flow | B7: ='Data Sheet'!B85 -> 8.14 | C7: ='Data Sheet'!C85 -> -31.4 | D7: ='Data Sheet'!D85 -> 18.39 | E7: ='Data Sheet'!E85 -> 364.05 | F7: ='Data Sheet'!F85 -> -295.4 | G7: ='Data Sheet'!G85 -> -712.19 | H7: ='Data Sheet'!H85 -> -958.15 | I7: ='Data Sheet'!I85 -> 249.83 | ... K7: ='Data Sheet'!K85 -> -86.37

Sheet Data Sheet
A1: COMPANY NAME | B1: ULTRATECH CEMENT LTD | E1: =IF(B2<>B3, "A NEW VERSION OF THE WORKSHEET IS AVAILABLE", "")
A2: LATEST VERSION | B2: 2.1 | E2: PLEASE DO NOT MAKE ANY CHANGES TO THIS SHEET
A3: CURRENT VERSION | B3: 2.1
A5: META
A6: Number of shares | B6: =IF(B9>0, B9/B8, 0) -> 29.463939
A7: Face Value | B7: 10
A8: Current Price | B8: 11750
A9: Market Capitalization | B9: 346201.28
A15: PROFIT & LOSS
A16: Report Date | B16: 42460 | C16: 42825 | D16: 43190 | E16: 43555 | F16: 43921 | G16: 44286 | H16: 44651 | I16: 45016 | J16: 45382 | K16: 45747
A17: Sales | B17: 25153.24 | C17: 25374.94 | D17: 30978.62 | E17: 41462.26 | F17: 42429.89 | G17: 44725.8 | H17: 52598.83 | I17: 63239.98 | J17: 70908.14 | K17: 75955.13
A18: Raw Material Cost | B18: 4436.12 | C18: 4416.9 | D18: 5399.98 | E18: 6936.74 | F18: 6875.89 | G18: 6635.66 | H18: 8348.15 | I18: 10233.17 | J18: 11986.27 | K18: 13691.46
A19: Change in Inventory | B19: 18.61 | C19: -75.69 | D19: 111.2 | E19: -46.35 | F19: 357.83 | G19: -450.15 | H19: 383.16 | I19: 518.21 | J19: 83.35 | K19: -12.27
A20: Power and Fuel | B20: 4579.25 | C20: 4271.98 | D20: 6334.07 | E20: 9436.14 | F20: 8516.87 | G20: 8331.18 | H20: 12137.26 | I20: 18491.32 | J20: 18283.32 | K20: 18419.15
A21: Other Mfr. Exp | B21: 1933.88 | C21: 1991.28 | D21: 2289.53 | E21: 3001.06 | F21: 3043.3 | G21: 3067.38 | H21: 3889.67 | I21: 4344.34 | J21: 4898.17 | K21: 5474.61
A22: Employee Cost | B22: 1466.49 | C22: 1547.77 | D22: 1831.81 | E22: 2309.43 | F22: 2522.64 | G22: 2363.33 | H22: 2545 | I22: 2751.31 | J22: 3051.99 | K22: 3619.25
A23: Selling and admin | B23: 7200.47 | C23: 7149.12 | D23: 8320.28 | E23: 11563.8 | F23: 11237.32 | G23: 11266.02 | H23: 13282.22 | I23: 15859.6 | J23: 18066.95 | K23: 19571.95
A24: Other Expenses | B24: 654.67 | C24: 709.76 | D24: 769.12 | E24: 821.8 | F24: 1345.73 | G24: 1044.17 | H24: 1265.34 | I24: 1458.6 | J24: 1726.23 | K24: 2369.56
A25: Other Income | B25: 463.81 | C25: 648.12 | D25: 241.97 | E25: 350.1 | F25: 651.06 | G25: 618.52 | H25: 669.43 | I25: 507.11 | J25: 556.96 | K25: 396.74
A26: Depreciation | B26: 1377.17 | C26: 1348.41 | D26: 1847.93 | E26: 2450.73 | F26: 2722.66 | G26: 2700.23 | H26: 2714.75 | I26: 2887.99 | J26: 3145.3 | K26: 4014.95
A27: Interest | B27: 566.3 | C27: 640.1 | D27: 1237.6 | E27: 1777.86 | F27: 1991.65 | G27: 1485.65 | H27: 944.71 | I27: 822.72 | J27: 968 | K27: 1650.54
... A31: Dividend Amount | B31: 260.71 | C31: 274.51 | D31: 288.34 | E31: 315.84 | F31: 375.22 | G31: 1068 | H31: 1096.95 | I31: 1097.02 | J31: 2020.83 | K31: 2283.77
A40: Quarters
A41: Report Date | B41: 45107 | C41: 45199 | D41: 45291 | E41: 45382 | F41: 45473 | G41: 45565 | H41: 45657 | I41: 45747 | J41: 45838 | K41: 45930
A42: Sales | B42: 17737.1 | C42: 16012.13 | D42: 16739.97 | E42: 20418.94 | F42: 18818.56 | G42: 16294.42 | H42: 17778.83 | I42: 23063.32 | J42: 21275.45 | K42: 19606.93
A43: Expenses | B43: 14687.92 | C43: 13461.24 | D43: 13485.4 | E43: 16305.02 | F43: 15801.46 | G43: 14268.68 | H43: 14885.35 | I43: 18455.65 | J43: 16869.42 | K43: 16518.27
A44: Other Income | B44: 177.43 | C44: 170.62 | D44: 146.24 | E44: 72.67 | F44: 83.31 | G44: 226.22 | H44: 247.32 | I44: 92.78 | J44: 141.85 | K44: 174.14
A45: Depreciation | B45: 749.07 | C45: 797.83 | D45: 783.48 | E45: 814.92 | F45: 917.93 | G45: 979.67 | H45: 992.78 | I45: 1124.57 | J45: 1106.78 | K45: 1147.68
A46: Interest | B46: 210.75 | C46: 233.94 | D46: 262.16 | E46: 261.15 | F46: 325.76 | G46: 392.99 | H46: 456.75 | I46: 475.04 | J46: 433.3 | K46: 459.29
A47: Profit before tax | B47: 2266.79 | C47: 1689.74 | D47: 2355.17 | E47: 3110.52 | F47: 1856.72 | G47: 879.3 | H47: 1691.27 | I47: 3100.84 | J47: 3007.8 | K47: 1655.83
A48: Tax | B48: 576.57 | C48: 409.36 | D48: 580.39 | E48: 851.94 | F48: 363.27 | G48: 171.34 | H48: 327.83 | I48: 626.05 | J48: 786.89 | K48: 417.85
A49: Net profit | B49: 1688.45 | C49: 1281.45 | D49: 1776.98 | E49: 2258.12 | F49: 1494.82 | G49: 702.82 | H49: 1359.43 | I49: 2482.04 | J49: 2225.9 | K49: 1231.58
A50: Operating Profit | B50: 3049.18 | C50: 2550.89 | D50: 3254.57 | E50: 4113.92 | F50: 3017.1 | G50: 2025.74 | H50: 2893.48 | I50: 4607.67 | J50: 4406.03 | K50: 3088.66
A55: BALANCE SHEET
A56: Report Date | B56: 42460 | C56: 42825 | D56: 43190 | E56: 43555 | F56: 43921 | G56: 44286 | H56: 44651 | I56: 45016 | J56: 45382 | K56: 45747
A57: Equity Share Capital | B57: 274.43 | C57: 274.51 | D57: 274.61 | E57: 274.64 | F57: 288.63 | G57: 288.65 | H57: 288.67 | I57: 288.69 | J57: 288.69 | K57: 294.68
A58: Reserves | B58: 21671.2 | C58: 24117.38 | D58: 26106.55 | E58: 33476.01 | F58: 38755.13 | G58: 43886.03 | H58: 50146.6 | I58: 54035.85 | J58: 59938.79 | K58: 70412.09
A59: Borrowings | B59: 10615.99 | C59: 8474.49 | D59: 19480.22 | E59: 25337 | F59: 23018.96 | G59: 21719.39 | H59: 11298.8 | I59: 11057.74 | J59: 11402.95 | K59: 24102.18
A60: Other Liabilities | B60: 8631.49 | C60: 9342.73 | D60: 11279.71 | E60: 17437.72 | F60: 17151.09 | G60: 20282.28 | H60: 22077.37 | I60: 25998.12 | J60: 29166.68 | K60: 38823.11
A61: Total | B61: 41193.11 | C61: 42209.11 | D61: 57141.09 | E61: 76525.37 | F61: 79213.81 | G61: 86176.35 | H61: 83811.44 | I61: 91380.4 | J61: 100797.11 | K61: 133632.06
...

Sheet Sheet1

Sheet Historical Data
A1: ULTRATECH CEMENT
F2: Figures in Crores
A3: Income Statement | B3: ='Data Sheet'!G16 -> 44286 | C3: ='Data Sheet'!H16 -> 44651 | D3: ='Data Sheet'!I16 -> 45016 | E3: ='Data Sheet'!J16 -> 45382 | F3: ='Data Sheet'!K16 -> 45747
A5: Sales | B5: ='Data Sheet'!G17 -> 44725.8 | C5: ='Data Sheet'!H17 -> 52598.83 | D5: ='Data Sheet'!I17 -> 63239.98 | E5: ='Data Sheet'!J17 -> 70908.14 | F5: ='Data Sheet'!K17 -> 75955.13
A6: Sales Growth | C6: =C5/B5-1 -> 0.17602882 | D6: =D5/C5-1 -> 0.20230773 | E6: =E5/D5-1 -> 0.12125494 | F6: =F5/E5-1 -> 0.071176454
A7: Other Income | B7: ='Data Sheet'!G25 -> 618.52 | C7: ='Data Sheet'!H25 -> 669.43 | D7: ='Data Sheet'!I25 -> 507.11 | E7: ='Data Sheet'!J25 -> 556.96 | F7: ='Data Sheet'!K25 -> 396.74
A8: Total Revenue | B8: =B5+B7 -> 45344.32 | C8: =C5+C7 -> 53268.26 | D8: =D5+D7 -> 63747.09 | E8: =E5+E7 -> 71465.1 | F8: =F5+F7 -> 76351.87
A9: Cost of Goods sold | B9: =IFERROR(SUM('Data Sheet'!G18,'Data Sheet'!G20,'Data Sheet'!G21,'Data Sheet'!G22-1*'Data Sheet'!G19),0) -> 20847.7 | C9: =IFERROR(SUM('Data Sheet'!H18,'Data Sheet'!H20,'Data Sheet'!H21,'Data Sheet'!H22-1*'Data Sheet'!H19),0) -> 26536.92 | D9: =IFERROR(SUM('Data Sheet'!I18,'Data Sheet'!I20,'Data Sheet'!I21,'Data Sheet'!I22-1*'Data Sheet'!I19),0) -> 35301.93 | E9: =IFERROR(SUM('Data Sheet'!J18,'Data Sheet'!J20,'Data Sheet'!J21,'Data Sheet'!J22-1*'Data Sheet'!J19),0) -> 38136.4 | F9: =IFERROR(SUM('Data Sheet'!K18,'Data Sheet'!K20,'Data Sheet'!K21,'Data Sheet'!K22-1*'Data Sheet'!K19),0) -> 41216.74
A10: COGS % Sales | B10: =B9/B5 -> 0.46612246 | C10: =C9/C5 -> 0.5045154 | D10: =D9/D5 -> 0.55822171 | E10: =E9/E5 -> 0.53782824 | F10: =F9/F5 -> 0.5426459
A11: Gross Profit | B11: =B5-B9 -> 23878.1 | C11: =C5-C9 -> 26061.91 | D11: =D5-D9 -> 27938.05 | E11: =E5-E9 -> 32771.74 | F11: =F5-F9 -> 34738.39
A12: Gross Profit Margin | B12: =B11/B5 -> 0.53387754 | C12: =C11/C5 -> 0.4954846 | D12: =D11/D5 -> 0.44177829 | E12: =E11/E5 -> 0.46217176 | F12: =F11/F5 -> 0.4573541
A13: S&G Expenses | B13: =IFERROR(SUM('Data Sheet'!G23:G24),0) -> 12310.19 | C13: =IFERROR(SUM('Data Sheet'!H23:H24),0) -> 14547.56 | D13: =IFERROR(SUM('Data Sheet'!I23:I24),0) -> 17318.2 | E13: =IFERROR(SUM('Data Sheet'!J23:J24),0) -> 19793.18 | F13: =IFERROR(SUM('Data Sheet'!K23:K24),0) -> 21941.51
A14: S&G Exp % Sales | B14: =B13/B5 -> 0.27523689 | C14: =C13/C5 -> 0.27657573 | D14: =D13/D5 -> 0.27384892 | E14: =E13/E5 -> 0.27913833 | F14: =F13/F5 -> 0.28887463
A15: EBITDA | B15: =B11-B13 -> 11567.91 | C15: =C11-C13 -> 11514.35 | D15: =D11-D13 -> 10619.85 | E15: =E11-E13 -> 12978.56 | F15: =F11-F13 -> 12796.88
A16: EBITDA Margin | B16: =B15/B5 -> 0.25864065 | C16: =C15/C5 -> 0.21890886 | D16: =D15/D5 -> 0.16792937 | E16: =E15/E5 -> 0.18303343 | F16: =F15/F5 -> 0.16847947
A17: Depreciation & Amort. | B17: =IFERROR('Data Sheet'!G26,0) -> 2700.23 | C17: =IFERROR('Data Sheet'!H26,0) -> 2714.75 | D17: =IFERROR('Data Sheet'!I26,0) -> 2887.99 | E17: =IFERROR('Data Sheet'!J26,0) -> 3145.3 | F17: =IFERROR('Data Sheet'!K26,0) -> 4014.95
A18: Depreciation % Sales | B18: =B17/B5 -> 0.060372984 | C18: =C17/C5 -> 0.051612365 | D18: =D17/D5 -> 0.045667155 | E18: =E17/E5 -> 0.04435739 | F18: =F17/F5 -> 0.052859497
A19: EBIT | B19: =B15-B17 -> 8867.68 | C19: =C15-C17 -> 8799.6 | D19: =D15-D17 -> 7731.86 | E19: =E15-E17 -> 9833.26 | F19: =F15-F17 -> 8781.93
A20: EBIT Margin | B20: =B19/B5 -> 0.19826767 | C20: =C19/C5 -> 0.1672965 | D20: =D19/D5 -> 0.12226221 | E20: =E19/E5 -> 0.13867604 | F20: =F19/F5 -> 0.11561997
A21: Interest | B21: ='Data Sheet'!G27 -> 1485.65 | C21: ='Data Sheet'!H27 -> 944.71 | D21: ='Data Sheet'!I27 -> 822.72 | E21: ='Data Sheet'!J27 -> 968 | F21: ='Data Sheet'!K27 -> 1650.54
A22: Interest % Sales | B22: =B21/B5 -> 0.033216846 | C22: =C21/C5 -> 0.017960666 | D22: =D21/D5 -> 0.013009492 | E22: =E21/E5 -> 0.013651465 | F22: =F21/F5 -> 0.021730461
A23: EBT | B23: =B19-B21 -> 7382.03 | C23: =C19-C21 -> 7854.89 | D23: =D19-D21 -> 6909.14 | E23: =E19-E21 -> 8865.26 | F23: =F19-F21 -> 7131.39
A24: EBT % Sales | B24: =B23/B5 -> 0.16505082 | C24: =C23/C5 -> 0.14933583 | D24: =D23/D5 -> 0.10925272 | E24: =E23/E5 -> 0.12502457 | F24: =F23/F5 -> 0.093889511
A25: Tax | B25: =IFERROR('Data Sheet'!G29,0) -> 2538.7 | C25: =IFERROR('Data Sheet'!H29,0) -> 1190.06 | D25: =IFERROR('Data Sheet'!I29,0) -> 2342.85 | E25: =IFERROR('Data Sheet'!J29,0) -> 2418.26 | F25: =IFERROR('Data Sheet'!K29,0) -> 1488.49
A26: Effective Tax Rate | B26: =B25/B23 -> 0.34390269 | C26: =C25/C23 -> 0.15150562 | D26: =D25/D23 -> 0.3390943 | E26: =E25/E23 -> 0.27277937 | F26: =F25/F23 -> 0.20872369
A27: Net Profit | B27: =B23-B25 -> 4843.33 | C27: =C23-C25 -> 6664.83 | D27: =D23-D25 -> 4566.29 | E27: =E23-E25 -> 6447 | F27: =F23-F25 -> 5642.9
A29: BALANCE SHEET | B29: ='Data Sheet'!G56 -> 44286 | C29: ='Data Sheet'!H56 -> 44651 | D29: ='Data Sheet'!I56 -> 45016 | E29: ='Data Sheet'!J56 -> 45382 | F29: ='Data Sheet'!K56 -> 45747
A31: Equity and Liabilities
A32: Equity share Capital | B32: =IFERROR('Data Sheet'!G57,0) -> 288.65 | C32: =IFERROR('Data Sheet'!H57,0) -> 288.67 | D32: =IFERROR('Data Sheet'!I57,0) -> 288.69 | E32: =IFERROR('Data Sheet'!J57,0) -> 288.69 | F32: =IFERROR('Data Sheet'!K57,0) -> 294.68
A33: Reserves | B33: =IFERROR('Data Sheet'!G58,0) -> 43886.03 | C33: =IFERROR('Data Sheet'!H58,0) -> 50146.6 | D33: =IFERROR('Data Sheet'!I58,0) -> 54035.85 | E33: =IFERROR('Data Sheet'!J58,0) -> 59938.79 | F33: =IFERROR('Data Sheet'!K58,0) -> 70412.09
A34: Borrowings | B34: =IFERROR('Data Sheet'!G59,0) -> 21719.39 | C34: =IFERROR('Data Sheet'!H59,0) -> 11298.8 | D34: =IFERROR('Data Sheet'!I59,0) -> 11057.74 | E34: =IFERROR('Data Sheet'!J59,0) -> 11402.95 | F34: =IFERROR('Data Sheet'!K59,0) -> 24102.18
A35: Other Liabilities | B35: =IFERROR('Data Sheet'!G60,0) -> 20282.28 | C35: =IFERROR('Data Sheet'!H60,0) -> 22077.37 | D35: =IFERROR('Data Sheet'!I60,0) -> 25998.12 | E35: =IFERROR('Data Sheet'!J60,0) -> 29166.68 | F35: =IFERROR('Data Sheet'!K60,0) -> 38823.11
A36: Total Liabilities | B36: =SUM(B32:B35) -> 86176.35 | C36: =SUM(C32:C35) -> 83811.44 | D36: =SUM(D32:D35) -> 91380.4 | E36: =SUM(E32:E35) -> 100797.11 | F36: =SUM(F32:F35) -> 133632.06
A38: Net block | B38: =IFERROR('Data Sheet'!G62,0) -> 55411.61 | C38: =IFERROR('Data Sheet'!H62,0) -> 55487.57 | D38: =IFERROR('Data Sheet'!I62,0) -> 59579 | E38: =IFERROR('Data Sheet'!J62,0) -> 62877.61 | F38: =IFERROR('Data Sheet'!K62,0) -> 94564.22
A39: Capital work in Progress | B39: =IFERROR('Data Sheet'!G63,0) -> 1686.68 | C39: =IFERROR('Data Sheet'!H63,0) -> 4784.67 | D39: =IFERROR('Data Sheet'!I63,0) -> 4040.39 | E39: =IFERROR('Data Sheet'!J63,0) -> 6811.18 | F39: =IFERROR('Data Sheet'!K63,0) -> 6234.19
A40: Investment | B40: =IFERROR('Data Sheet'!G64,0) -> 12178.11 | C40: =IFERROR('Data Sheet'!H64,0) -> 6335.77 | D40: =IFERROR('Data Sheet'!I64,0) -> 7296.95 | E40: =IFERROR('Data Sheet'!J64,0) -> 8248.95 | F40: =IFERROR('Data Sheet'!K64,0) -> 5156.47
A41: Other Assets | B41: =IFERROR(SUM('Data Sheet'!G65-SUM('Data Sheet'!G67:G69)),0) -> 8302.7 | C41: =IFERROR(SUM('Data Sheet'!H65-SUM('Data Sheet'!H67:H69)),0) -> 8177.06 | D41: =IFERROR(SUM('Data Sheet'!I65-SUM('Data Sheet'!I67:I69)),0) -> 8835.62 | E41: =IFERROR(SUM('Data Sheet'!J65-SUM('Data Sheet'!J67:J69)),0) -> 9468.26 | F41: =IFERROR(SUM('Data Sheet'!K65-SUM('Data Sheet'!K67:K69)),0) -> 10550.63
A42: Total Non Current Assests | B42: =SUM(B38:B41) -> 77579.1 | C42: =SUM(C38:C41) -> 74785.07 | D42: =SUM(D38:D41) -> 79751.96 | E42: =SUM(E38:E41) -> 87406 | F42: =SUM(F38:F41) -> 116505.51
A44: Receivables | B44: =IFERROR('Data Sheet'!G67,0) -> 2571.73 | C44: =IFERROR('Data Sheet'!H67,0) -> 3071.61 | D44: =IFERROR('Data Sheet'!I67,0) -> 3867.02 | E44: =IFERROR('Data Sheet'!J67,0) -> 4278.16 | F44: =IFERROR('Data Sheet'!K67,0) -> 5890.25
A45: Receivables % Sales | B45: =B44/B5 -> 0.057499922 | C45: =C44/C5 -> 0.058396926 | D45: =D44/D5 -> 0.061148343 | E45: =E44/E5 -> 0.060333835 | F45: =F44/F5 -> 0.077549074
...

Sheet Forecasting
A2: FUTURE PROJECTION | B2: 46082 | C2: 46447 | D2: 46813 | E2: 47178 | F2: 11018
A4: Sales Growth | B4: {=TRANSPOSE(D21:D25)} -> 0.12850794 | C4: 0.09422745 | D4: 0.086113221 | E4: 0.079285676 | F4: 0.073461251
A5: COGS % of Sales | B5: {=TRANSPOSE(D34:D38)} -> 0.56126306 | C5: 0.56873217 | D5: 0.57501689 | E5: 0.58037824 | F5: 0.5850058
A6: Marginal Tax Rate | B6: 0.25 | C6: 0.25 | D6: 0.25 | E6: 0.25 | F6: 0.25
A7: Closing PPE as % of Sales | B7: 1.03 | C7: 1.03 | D7: 1.03 | E7: 1.03 | F7: 1.03
A8: S&G Exp % of Sales | B8: 0.28 | C8: 0.28 | D8: 0.28 | E8: 0.28 | F8: 0.28
A9: Depreciation (% of PPE opening Balance) | B9: 0.05 | C9: 0.05 | D9: 0.05 | E9: 0.05 | F9: 0.05
A10: Interest Rate(% of Opening Debt) | B10: 0.08 | C10: 0.08 | D10: 0.08 | E10: 0.08 | F10: 0.08
A14: Forecasting Sales Growth
A15: Year Weight | B15: Year | C15: Sales | D15: Sales Growth
A16: 1 | B16: 44286 | C16: 44725.8
A17: 2 | B17: 44651 | C17: 52598.83 | D17: 0.17602882
A18: 3 | B18: 45016 | C18: 63239.98 | D18: 0.20230773
A19: 4 | B19: 45382 | C19: 70908.14 | D19: 0.12125494
A20: 5 | B20: 45747 | C20: 75955.13 | D20: 0.071176454
A21: 6 | B21: 46082 | C21: =FORECAST(A21,$C$16:$C$20,$A$16:$A$20) -> 85715.967 | D21: =C21/C20-1 -> 0.12850794
A22: 7 | B22: 46447 | C22: =FORECAST(A22,$C$16:$C$20,$A$16:$A$20) -> 93792.764 | D22: =C22/C21-1 -> 0.09422745
A23: 8 | B23: 46813 | C23: =FORECAST(A23,$C$16:$C$20,$A$16:$A$20) -> 101869.56 | D23: =C23/C22-1 -> 0.086113221
A24: 9 | B24: 47178 | C24: =FORECAST(A24,$C$16:$C$20,$A$16:$A$20) -> 109946.36 | D24: =C24/C23-1 -> 0.079285676
A25: 10 | B25: 11018 | C25: =FORECAST(A25,$C$16:$C$20,$A$16:$A$20) -> 118023.15 | D25: =C25/C24-1 -> 0.073461251
A27: Forecasting COGS as % of Sales
A28: Year Weight | B28: Year | C28: COGS | D28: COGS as % of Sales
A29: 1 | B29: 44286 | C29: 20847.7 | D29: 0.46612246
A30: 2 | B30: 44651 | C30: 26536.92 | D30: 0.5045154
A31: 3 | B31: 45016 | C31: 35301.93 | D31: 0.55822171
A32: 4 | B32: 45382 | C32: 38136.4 | D32: 0.53782824
A33: 5 | B33: 45747 | C33: 41216.74 | D33: 0.5426459
A34: 6 | B34: 46082 | C34: =FORECAST(A34,$C$29:$C$33,$A$29:$A$33) -> 48109.206 | D34: =C34/C21 -> 0.56126306
A35: 7 | B35: 46447 | C35: =FORECAST(A35,$C$29:$C$33,$A$29:$A$33) -> 53342.962 | D35: =C35/C22 -> 0.56873217
A36: 8 | B36: 46813 | C36: =FORECAST(A36,$C$29:$C$33,$A$29:$A$33) -> 58576.718 | D36: =C36/C23 -> 0.57501689
A37: 9 | B37: 47178 | C37: =FORECAST(A37,$C$29:$C$33,$A$29:$A$33) -> 63810.474 | D37: =C37/C24 -> 0.58037824
A38: 10 | B38: 11018 | C38: =FORECAST(A38,$C$29:$C$33,$A$29:$A$33) -> 69044.23 | D38: =C38/C25 -> 0.5850058
A40: Forecasting S&G Exp as % of Sales
A41: Year Weight | B41: Year | C41: S&G Exp | D41: S&G Exp as % of Sales
A42: 1 | B42: 44286 | C42: 12310.19 | D42: 0.27523689
A43: 2 | B43: 44651 | C43: 14547.56 | D43: 0.27657573 | E43: =AVERAGE(D42:D46) -> 0.2787349
A44: 3 | B44: 45016 | C44: 17318.2 | D44: 0.27384892
A45: 4 | B45: 45382 | C45: 19793.18 | D45: 0.27913833
A46: 5 | B46: 45747 | C46: 21941.51 | D46: 0.28887463
A48: Forecasting of Depreciation (% of PPE opening Balance)
...

Sheet PIS
F1: Figures in Crores
A2: FORECASTING OF INCOME STATEMENT | B2: 46082 | C2: 46447 | D2: 46813 | E2: 47178 | F2: 11018
A3: Sales | B3: ='Historical Data'!F5*(1+Forecasting!B4) -> 85715.967 | C3: =B3*(1+Forecasting!C4) -> 93792.764 | D3: =C3*(1+Forecasting!D4) -> 101869.56 | E3: =D3*(1+Forecasting!E4) -> 109946.36 | F3: =E3*(1+Forecasting!F4) -> 118023.15
A4: COGS | B4: =B3*Forecasting!B5 -> 48109.206 | C4: =C3*Forecasting!C5 -> 53342.962 | D4: =D3*Forecasting!D5 -> 58576.718 | E4: =E3*Forecasting!E5 -> 63810.474 | F4: =F3*Forecasting!F5 -> 69044.23
A5: Gross Profit | B5: =B3-B4 -> 37606.761 | C5: =C3-C4 -> 40449.802 | D5: =D3-D4 -> 43292.843 | E5: =E3-E4 -> 46135.884 | F5: =F3-F4 -> 48978.925
A6: S&G Expenses | B6: =B3*Forecasting!B8 -> 24000.471 | C6: =C3*Forecasting!C8 -> 26261.974 | D6: =D3*Forecasting!D8 -> 28523.477 | E6: =E3*Forecasting!E8 -> 30784.98 | F6: =F3*Forecasting!F8 -> 33046.483
A7: EBITDA | B7: =B5-B6 -> 13606.29 | C7: =C5-C6 -> 14187.828 | D7: =D5-D6 -> 14769.366 | E7: =E5-E6 -> 15350.904 | F7: =F5-F6 -> 15932.442
A8: Depreciation | B8: =PBS!B22*PIS!B9 -> 3238.1969 | C8: =PBS!C22*PIS!C9 -> 3335.3428 | D8: =PBS!D22*PIS!D9 -> 3435.4031 | E8: =PBS!E22*PIS!E9 -> 3538.4652 | F8: =PBS!F22*PIS!F9 -> 3644.6192
B9: =Forecasting!B9 -> 0.05 | C9: =Forecasting!C9 -> 0.05 | D9: =Forecasting!D9 -> 0.05 | E9: =Forecasting!E9 -> 0.05 | F9: =Forecasting!F9 -> 0.05
A10: EBIT | B10: =B7-B8 -> 10368.093 | C10: =C7-C8 -> 10852.485 | D10: =D7-D8 -> 11333.963 | E10: =E7-E8 -> 11812.439 | F10: =F7-F8 -> 12287.822
A11: Interest | B11: =PBS!B12*PIS!B12 -> 967.79117 | C11: =PBS!C12*PIS!C12 -> 996.82491 | D11: =PBS!D12*PIS!D12 -> 1026.7297 | E11: =PBS!E12*PIS!E12 -> 1057.5315 | F11: =PBS!F12*PIS!F12 -> 1089.2575
B12: =Forecasting!B10 -> 0.08 | C12: =Forecasting!C10 -> 0.08 | D12: =Forecasting!D10 -> 0.08 | E12: =Forecasting!E10 -> 0.08 | F12: =Forecasting!F10 -> 0.08
A13: EBT | B13: =B10-B11 -> 9400.3022 | C13: =C10-C11 -> 9855.6603 | D13: =D10-D11 -> 10307.233 | E13: =E10-E11 -> 10754.907 | F13: =F10-F11 -> 11198.565
A14: Tax | B14: =B13*B15 -> 2350.0755 | C14: =C13*C15 -> 2463.9151 | D14: =D13*D15 -> 2576.8083 | E14: =E13*E15 -> 2688.7268 | F14: =F13*F15 -> 2799.6412
A15: (Marginal Tax Rate) | B15: 0.25 | C15: 0.25 | D15: 0.25 | E15: 0.25 | F15: 0.25
A16: Net Profit | B16: =B13-B14 -> 7050.2266 | C16: =C13-C14 -> 7391.7453 | D16: =D13-D14 -> 7730.4249 | E16: =E13-E14 -> 8066.1803 | F16: =F13-F14 -> 8398.9237
A18: Dividend Amount | B18: =B16*B19 -> 2467.5793 | C18: =C16*C19 -> 2587.1108 | D18: =D16*D19 -> 2705.6487 | E18: =E16*E19 -> 2823.1631 | F18: =F16*F19 -> 2939.6233
B19: 0.35 | C19: 0.35 | D19: 0.35 | E19: 0.35 | F19: 0.35

Sheet PBS
F1: Figures in Crores
A2: FORECASTING OF BALANCE SHEET | B2: 46082 | C2: 46447 | D2: 46813 | E2: 47178 | F2: 11018
A4: Equity and Liabilities
A5: Equity
A6: Equity Capital | B6: ='Historical Data'!F32 -> 294.68 | C6: 294.68 | D6: 294.68 | E6: 294.68 | F6: 294.68
A7: Retained Earning( Assumed) | B7: ='Historical Data'!F53+PIS!B16-PIS!B18-4105.07 -> 74248.797 | C7: =B7+PIS!C16-PIS!C18+3374.2 -> 82427.632 | D7: =C7+PIS!D16-PIS!D18+3475.43 -> 90927.838 | E7: =D7+PIS!E16-PIS!E18+3579.69 -> 99750.545 | F7: =E7+PIS!F16-PIS!F18+3687.08 -> 108896.93
A8: Total Equity | B8: =SUM(B6:B7) -> 74543.477 | C8: =SUM(C6:C7) -> 82722.312 | D8: =SUM(D6:D7) -> 91222.518 | E8: =SUM(E6:E7) -> 100045.23 | F8: =SUM(F6:F7) -> 109191.61
A10: Liabilities
A11: Non current Liabilities
A12: Borrowings | B12: =PCFS!D50 -> 12097.39 | C12: =PCFS!E50 -> 12460.311 | D12: =PCFS!F50 -> 12834.121 | E12: =PCFS!G50 -> 13219.144 | F12: =PCFS!H50 -> 13615.719
A14: Current Liabilities
A15: Trade Payables | B15: =PIS!B3*PBS!B16 -> 5142.958 | C15: =PIS!C3*PBS!C16 -> 5627.5658 | D15: =PIS!D3*PBS!D16 -> 6112.1737 | E15: =PIS!E3*PBS!E16 -> 6596.7815 | F15: =PIS!F3*PBS!F16 -> 7081.3893
A16: (Assumption:- 6% of Sales) | B16: 0.06 | C16: 0.06 | D16: 0.06 | E16: 0.06 | F16: 0.06
A18: Total Liabilities | B18: =SUM(B8,B12,B15) -> 91783.825 | C18: =SUM(C8,C12,C15) -> 100810.19 | D18: =SUM(D8,D12,D15) -> 110168.81 | E18: =SUM(E8,E12,E15) -> 119861.15 | F18: =SUM(F8,F12,F15) -> 129888.71
A20: Assets
A21: Non Current Assets
A22: Net Blocks (PPE) | B22: =('Historical Data'!E38+'Historical Data'!E38*PBS!B23) -> 64763.938 | C22: =(B22+B22*C23) -> 66706.856 | D22: =(C22+C22*D23) -> 68708.062 | E22: =(D22+D22*E23) -> 70769.304 | F22: =(E22+E22*F23) -> 72892.383
B23: 0.03 | C23: 0.03 | D23: 0.03 | E23: 0.03 | F23: 0.03
A24: Current Assets
A25: Receivables | B25: =PIS!B3*PBS!B26 -> 6857.2774 | C25: =PIS!C3*PBS!C26 -> 7503.4211 | D25: =PIS!D3*PBS!D26 -> 8149.5649 | E25: =PIS!E3*PBS!E26 -> 8795.7086 | F25: =PIS!F3*PBS!F26 -> 9441.8524
A26: (% of Sales) | B26: 0.08 | C26: 0.08 | D26: 0.08 | E26: 0.08 | F26: 0.08
A27: Inventories | B27: =PIS!B4*PBS!B28 -> 10102.933 | C27: =PIS!C4*PBS!C28 -> 11202.022 | D27: =PIS!D4*PBS!D28 -> 12301.111 | E27: =PIS!E4*PBS!E28 -> 13400.2 | F27: =PIS!F4*PBS!F28 -> 14499.288
B28: 0.21 | C28: 0.21 | D28: 0.21 | E28: 0.21 | F28: 0.21
A29: Cash & Bank | B29: =PCFS!D27 -> 10059.674 | C29: =PCFS!E27 -> 15397.888 | D29: =PCFS!F27 -> 21010.071 | E29: =PCFS!G27 -> 26895.935 | F29: =PCFS!H27 -> 33055.187
A30: Total Assets | B30: =B22+B25+B27+B29 -> 91783.823 | C30: =C22+C25+C27+C29 -> 100810.19 | D30: =D22+D25+D27+D29 -> 110168.81 | E30: =E22+E25+E27+E29 -> 119861.15 | F30: =F22+F25+F27+F29 -> 129888.71
B32: =B30-B18 -> -0.002119 | C32: =C30-C18 -> -0.00093356999 | D32: =D30-D18 -> -0.0037125771 | E32: =E30-E18 -> -0.0036749544 | F32: =F30-F18 -> -0.002936203

Sheet PCFS
H1: Figures in Crores
A2: FORECASTING OF CASH FLOW STATEMENT | B2: 45352 | C2: 45717 | D2: 46082 | E2: 46447 | F2: 46813 | G2: 47178 | H2: 11018
A4: Cash Flow from Operating Activities
A5: Profit before Tax | B5: ='Historical Data'!E23 -> 8865.26 | C5: ='Historical Data'!F23 -> 7131.39 | D5: =PIS!B13 -> 9400.3022 | E5: =PIS!C13 -> 9855.6603 | F5: =PIS!D13 -> 10307.233 | G5: =PIS!E13 -> 10754.907 | H5: =PIS!F13 -> 11198.565
A6: Adjustment for Non cash/ Non Operating Expenses
A7: Add:- Depreciation | B7: ='Historical Data'!E17 -> 3145.3 | C7: ='Historical Data'!F17 -> 4014.95 | D7: =PIS!B8 -> 3238.1969 | E7: =PIS!C8 -> 3335.3428 | F7: =PIS!D8 -> 3435.4031 | G7: =PIS!E8 -> 3538.4652 | H7: =PIS!F8 -> 3644.6192
A8: Add:- Interest | B8: ='Historical Data'!E21 -> 968 | C8: ='Historical Data'!F21 -> 1650.54 | D8: =PIS!B11 -> 967.79117 | E8: =PIS!C11 -> 996.82491 | F8: =PIS!D11 -> 1026.7297 | G8: =PIS!E11 -> 1057.5315 | H8: =PIS!F11 -> 1089.2575
A9: Operating Income Before Working Capital Changes | B9: =SUM(B5,B7:B8) -> 12978.56 | C9: =SUM(C5,C7:C8) -> 12796.88 | D9: =SUM(D5,D7:D8) -> 13606.29 | E9: =SUM(E5,E7:E8) -> 14187.828 | F9: =SUM(F5,F7:F8) -> 14769.366 | G9: =SUM(G5,G7:G8) -> 15350.904 | H9: =SUM(H5,H7:H8) -> 15932.442
A10: Less:- Changes in Working Capital | C10: =C39 -> 2845.33 | D10: =D39 -> 921.3304 | E10: =E39 -> 1260.6247 | F10: =F39 -> 1260.6247 | G10: =G39 -> 1260.6247 | H10: =H39 -> 1260.6247
A11: Operating Income After Working Capital Changes | C11: =C9-C10 -> 9951.55 | D11: =D9-D10 -> 12684.96 | E11: =E9-E10 -> 12927.203 | F11: =F9-F10 -> 13508.741 | G11: =G9-G10 -> 14090.279 | H11: =H9-H10 -> 14671.817
A12: Less:- Tax | C12: ='Historical Data'!F25 -> 1488.49 | D12: =PIS!B14 -> 2350.0755 | E12: =PIS!C14 -> 2463.9151 | F12: =PIS!D14 -> 2576.8083 | G12: =PIS!E14 -> 2688.7268 | H12: =PIS!F14 -> 2799.6412
A13: Cash Flow from Operating Activities | C13: =C11-C12 -> 8463.06 | D13: =D11-D12 -> 10334.884 | E13: =E11-E12 -> 10463.288 | F13: =F11-F12 -> 10931.933 | G13: =G11-G12 -> 11401.552 | H13: =H11-H12 -> 11872.176
A15: Cash Flow from Investing Activities
A16: Purchase Of PPE(Net blocks) | C16: =-C46 -> -1016.6783 | D16: =-D46 -> -2719.6712 | E16: =-E46 -> -1904.0598 | F16: =-F46 -> -1961.1816 | G16: =-G46 -> -2020.017 | H16: =-H46 -> -2080.6175
A17: Cash Flow from Investing Activities | C17: =C16 -> -1016.6783 | D17: =D16 -> -2719.6712 | E17: =E16 -> -1904.0598 | F17: =F16 -> -1961.1816 | G17: =G16 -> -2020.017 | H17: =H16 -> -2080.6175
A19: Cash Flow from Financing Activities
A20: Borrowings | C20: =C51 -> 342.0885 | D20: =D51 -> 352.35116 | E20: =E51 -> 362.92169 | F20: =F51 -> 373.80934 | G20: =G51 -> 385.02362 | H20: =H51 -> 396.57433
A21: Dividend Paid | C21: =-'Historical Data'!F52 -> -2283.77 | D21: =-PIS!B18 -> -2467.5793 | E21: =-PIS!C18 -> -2587.1108 | F21: =-PIS!D18 -> -2705.6487 | G21: =-PIS!E18 -> -2823.1631 | H21: =-PIS!F18 -> -2939.6233
A22: Interest Paid | C22: =-'Historical Data'!F21 -> -1650.54 | D22: =-PIS!B11 -> -967.79117 | E22: =-PIS!C11 -> -996.82491 | F22: =-PIS!D11 -> -1026.7297 | G22: =-PIS!E11 -> -1057.5315 | H22: =-PIS!F11 -> -1089.2575
A23: Cash Flow from Financing Activities | C23: =SUM(C20:C22) -> -3592.2215 | D23: =SUM(D20:D22) -> -3083.0193 | E23: =SUM(E20:E22) -> -3221.0141 | F23: =SUM(F20:F22) -> -3358.569 | G23: =SUM(G20:G22) -> -3495.671 | H23: =SUM(H20:H22) -> -3632.3065
A25: Total Cash Flow | C25: =SUM(C13,C17,C23) -> 3854.1602 | D25: =SUM(D13,D17,D23) -> 4532.1937 | E25: =SUM(E13,E17,E23) -> 5338.2144 | F25: =SUM(F13,F17,F23) -> 5612.1823 | G25: =SUM(G13,G17,G23) -> 5885.8643 | H25: =SUM(H13,H17,H23) -> 6159.2517
A26: Cash and Cash Equivalent at the Beginning | C26: ='Historical Data'!F48 -> 1673.32 | D26: =C27 -> 5527.4802 | E26: =D27 -> 10059.674 | F26: =E27 -> 15397.888 | G26: =F27 -> 21010.071 | H26: =G27 -> 26895.935
A27: Cash and Cash Equivalent at the End | C27: =SUM(C25:C26) -> 5527.4802 | D27: =SUM(D25:D26) -> 10059.674 | E27: =SUM(E25:E26) -> 15397.888 | F27: =SUM(F25:F26) -> 21010.071 | G27: =SUM(G25:G26) -> 26895.935 | H27: =SUM(H25:H26) -> 33055.187
A29: Supporting Schedule
A31: Working Capital Schedule | B31: 45352 | C31: 45717 | D31: 46082 | E31: 46447 | F31: 46813 | G31: 47178 | H31: 11018
A33: Trade Payables | B33: ='Historical Data'!F5*PBS!B16 -> 4557.3078 | C33: ='Historical Data'!F5*PBS!B16 -> 4557.3078 | D33: =PBS!B15 -> 5142.958 | E33: =PBS!C15 -> 5627.5658 | F33: =PBS!D15 -> 6112.1737 | G33: =PBS!E15 -> 6596.7815 | H33: =PBS!F15 -> 7081.3893
A34: Total Current Liability | B34: =B33 -> 4557.3078 | C34: =C33 -> 4557.3078 | D34: =D33 -> 5142.958 | E34: =E33 -> 5627.5658 | F34: =F33 -> 6112.1737 | G34: =G33 -> 6596.7815 | H34: =H33 -> 7081.3893
A35: Receivables | B35: ='Historical Data'!E44 -> 4278.16 | C35: ='Historical Data'!F44 -> 5890.25 | D35: =PBS!B25 -> 6857.2774 | E35: =PBS!C25 -> 7503.4211 | F35: =PBS!D25 -> 8149.5649 | G35: =PBS!E25 -> 8795.7086 | H35: =PBS!F25 -> 9441.8524
A36: Inventory | B36: ='Historical Data'!E46 -> 8329.74 | C36: ='Historical Data'!F46 -> 9562.98 | D36: =PBS!B27 -> 10102.933 | E36: =PBS!C27 -> 11202.022 | F36: =PBS!D27 -> 12301.111 | G36: =PBS!E27 -> 13400.2 | H36: =PBS!F27 -> 14499.288
A37: Total Current Assets | B37: =SUM(B35:B36) -> 12607.9 | C37: =SUM(C35:C36) -> 15453.23 | D37: =SUM(D35:D36) -> 16960.211 | E37: =SUM(E35:E36) -> 18705.443 | F37: =SUM(F35:F36) -> 20450.676 | G37: =SUM(G35:G36) -> 22195.908 | H37: =SUM(H35:H36) -> 23941.141
A38: Working Capital | B38: =B37-B34 -> 8050.5922 | C38: =C37-C34 -> 10895.922 | D38: =D37-D34 -> 11817.253 | E38: =E37-E34 -> 13077.877 | F38: =F37-F34 -> 14338.502 | G38: =G37-G34 -> 15599.127 | H38: =H37-H34 -> 16859.751
A39: Change in Working Capital | C39: =C38-B38 -> 2845.33 | D39: =D38-C38 -> 921.3304 | E39: =E38-D38 -> 1260.6247 | F39: =F38-E38 -> 1260.6247 | G39: =G38-F38 -> 1260.6247 | H39: =H38-G38 -> 1260.6247
A41: PPE Schedule | B41: 45352 | C41: 45717 | D41: 46082 | E41: 46447 | F41: 46813 | G41: 47178 | H41: 11018
A43: Purchase of PPE(Net Block) | B43: ='Historical Data'!E38 -> 62877.61 | C43: =B43+B43*PBS!B23 -> 64763.938 | D43: =C43+C43*PBS!C23 -> 66706.856 | E43: =D43+D43*PBS!D23 -> 68708.062 | F43: =E43+E43*PBS!E23 -> 70769.304 | G43: =F43+F43*PBS!F23 -> 72892.383 | H43: =G43+G43*PBS!F23 -> 75079.155
A44: Less:- Depreciation | B44: ='Historical Data'!E17 -> 3145.3 | C44: ='Historical Data'!F17 -> 4014.95 | D44: =PIS!B8 -> 3238.1969 | E44: =PIS!C8 -> 3335.3428 | F44: =PIS!D8 -> 3435.4031 | G44: =PIS!E8 -> 3538.4652 | H44: =PIS!F8 -> 3644.6192
B45: =B43-B44 -> 59732.31 | C45: =C43-C44 -> 60748.988 | D45: =D43-D44 -> 63468.66 | E45: =E43-E44 -> 65372.719 | F45: =F43-F44 -> 67333.901 | G45: =G43-G44 -> 69353.918 | H45: =H43-H44 -> 71434.535
A46: Change in PPE | C46: =C45-B45 -> 1016.6783 | D46: =D45-C45 -> 2719.6712 | E46: =E45-D45 -> 1904.0598 | F46: =F45-E45 -> 1961.1816 | G46: =G45-F45 -> 2020.017 | H46: =H45-G45 -> 2080.6175
A48: Borrowing Schedule | B48: 45352 | C48: 45717 | D48: 46082 | E48: 46447 | F48: 46813 | G48: 47178 | H48: 11018
A50: Borrowings | B50: ='Historical Data'!E34 -> 11402.95 | C50: =B50+B50*C52 -> 11745.039 | D50: =C50+C50*D52 -> 12097.39 | E50: =D50+D50*E52 -> 12460.311 | F50: =E50+E50*F52 -> 12834.121 | G50: =F50+F50*G52 -> 13219.144 | H50: =G50+G50*H52 -> 13615.719
A51: Change in Borrowings | C51: =C50-B50 -> 342.0885 | D51: =D50-C50 -> 352.35116 | E51: =E50-D50 -> 362.92169 | F51: =F50-E50 -> 373.80934 | G51: =G50-F50 -> 385.02362 | H51: =H50-G50 -> 396.57433
...

Sheet Value of Firm
H1: Figures in Crores
A2: FREE CASH FLOW TO FIRM | B2: 45352 | C2: 45717 | D2: 46082 | E2: 46447 | F2: 46813 | G2: 47178 | H2: 11018 | J2: TERMINAL VALUE | K2: VALUE OF FIRM
A4: EBIT | B4: ='Historical Data'!E19 -> 9833.26 | C4: ='Historical Data'!F19 -> 8781.93 | D4: =PIS!B10 -> 10368.093 | E4: =PIS!C10 -> 10852.485 | F4: =PIS!D10 -> 11333.963 | G4: =PIS!E10 -> 11812.439 | H4: =PIS!F10 -> 12287.822
A5: Less:- Tax | B5: =-('Value of Firm'!B4*Forecasting!B6) -> -2458.315 | C5: =-('Value of Firm'!C4*Forecasting!C6) -> -2195.4825 | D5: =-(D4*Forecasting!B6) -> -2592.0233 | E5: =-(E4*Forecasting!C6) -> -2713.1213 | F5: =-(F4*Forecasting!D6) -> -2833.4907 | G5: =-(G4*Forecasting!E6) -> -2953.1096 | H5: =-(H4*Forecasting!F6) -> -3071.9556
A6: NOPLAT | B6: =SUM(B4:B5) -> 7374.945 | C6: =SUM(C4:C5) -> 6586.4475 | D6: =SUM(D4:D5) -> 7776.07 | E6: =SUM(E4:E5) -> 8139.3639 | F6: =SUM(F4:F5) -> 8500.4721 | G6: =SUM(G4:G5) -> 8859.3289 | H6: =SUM(H4:H5) -> 9215.8668
A7: Add:- Depreciation | B7: ='Historical Data'!E17 -> 3145.3 | C7: ='Historical Data'!F17 -> 4014.95 | D7: =PIS!B8 -> 3238.1969 | E7: =PIS!C8 -> 3335.3428 | F7: =PIS!D8 -> 3435.4031 | G7: =PIS!E8 -> 3538.4652 | H7: =PIS!F8 -> 3644.6192
A8: Less:- Change in working Capital | B8: =-PCFS!B39 -> 0 | C8: =-PCFS!C39 -> -2845.33 | D8: =-PCFS!D39 -> -921.3304 | E8: =-PCFS!E39 -> -1260.6247 | F8: =-PCFS!F39 -> -1260.6247 | G8: =-PCFS!G39 -> -1260.6247 | H8: =-PCFS!H39 -> -1260.6247
A9: Less:- Change in Capital Expenditure | B9: =-PCFS!B46 -> 0 | C9: =-PCFS!C46 -> -1016.6783 | D9: =-PCFS!D46 -> -2719.6712 | E9: =-PCFS!E46 -> -1904.0598 | F9: =-PCFS!F46 -> -1961.1816 | G9: =-PCFS!G46 -> -2020.017 | H9: =-PCFS!H46 -> -2080.6175
A10: FCFF | B10: =SUM(B6:B9) -> 10520.245 | C10: =SUM(C6:C9) -> 6739.3892 | D10: =SUM(D6:D9) -> 7373.2653 | E10: =SUM(E6:E9) -> 8310.0223 | F10: =SUM(F6:F9) -> 8714.0689 | G10: =SUM(G6:G9) -> 9117.1524 | H10: =SUM(H6:H9) -> 9519.2438 | J10: =H10*(1+H30)/(E38-H30) -> 238747.63
A11: PV of FCFF | D11: =D10*(1/(1+$E$38)^D54) -> 6918.4089 | E11: =E10*(1/(1+$E$38)^E54) -> 7316.3576 | F11: =F10*(1/(1+$E$38)^F54) -> 7198.7998 | G11: =G10*(1/(1+$E$38)^G54) -> 7067.1562 | H11: =H10*(1/(1+$E$38)^H54) -> 6923.637 | J11: =H11*(1+H30)/(E38-H30) -> 173648.45 | K11: =SUM(D11:H11,J11) -> 209072.81
A13: FREE CASH FLOW TO EQUITY | B13: 45352 | C13: 45717 | D13: 46082 | E13: 46447 | F13: 46813 | G13: 47178 | H13: 11018
A15: FCFF | C15: =C10 -> 6739.3892 | D15: =D10 -> 7373.2653 | E15: =E10 -> 8310.0223 | F15: =F10 -> 8714.0689 | G15: =G10 -> 9117.1524 | H15: =H10 -> 9519.2438
A16: Less:- Interest(1-Tax) | C16: =-('Historical Data'!F21-('Historical Data'!F21*'Historical Data'!F26)) -> -1306.0332 | D16: =-(PIS!B11-(PIS!B11*Forecasting!B6)) -> -725.84338 | E16: =-(PIS!C11-(PIS!C11*Forecasting!C6)) -> -747.61868 | F16: =-(PIS!D11-(PIS!D11*Forecasting!D6)) -> -770.04724 | G16: =-(PIS!E11-(PIS!E11*Forecasting!E6)) -> -793.14866 | H16: =-(PIS!F11-(PIS!F11*Forecasting!F6)) -> -816.94312
A17: Net Debt | C17: =-PCFS!C51 -> -342.0885 | D17: =-PCFS!D51 -> -352.35116 | E17: =-PCFS!E51 -> -362.92169 | F17: =-PCFS!F51 -> -373.80934 | G17: =-PCFS!G51 -> -385.02362 | H17: =-PCFS!H51 -> -396.57433
A18: FCFE | C18: =SUM(C15:C17) -> 5091.2675 | D18: =SUM(D15:D17) -> 6295.0707 | E18: =SUM(E15:E17) -> 7199.4819 | F18: =SUM(F15:F17) -> 7570.2124 | G18: =SUM(G15:G17) -> 7938.9801 | H18: =SUM(H15:H17) -> 8305.7263 | J18: =H18*(1+H30)/(B46-H30) -> 203383.64
A19: PV of FCFE | D19: =D18*(1/(1+$B$46)^D54) -> 5901.2452 | E19: =E18*(1/(1+$B$46)^E54) -> 6326.8471 | F19: =F18*(1/(1+$B$46)^F54) -> 6236.4466 | G19: =G18*(1/(1+$B$46)^G54) -> 6131.0789 | H19: =H18*(1/(1+$B$46)^H54) -> 6013.0229 | J19: =H19*(1+H30)/(B46-H30) -> 147241.85 | K19: =SUM(D19:H19,J19) -> 177850.49
A21: WORKING FOR GROWTH RATE | B21: 45352 | C21: 45717 | D21: 46082 | E21: 46447 | F21: 46813 | G21: 47178 | H21: 11018
A23: Dividend Amount | B23: ='Historical Data'!E52 -> 2020.83 | C23: ='Historical Data'!F52 -> 2283.77 | D23: =PIS!B18 -> 2467.5793 | E23: =PIS!C18 -> 2587.1108 | F23: =PIS!D18 -> 2705.6487 | G23: =PIS!E18 -> 2823.1631 | H23: =PIS!F18 -> 2939.6233
A24: Net Income | B24: ='Historical Data'!E27 -> 6447 | C24: ='Historical Data'!F27 -> 5642.9 | D24: =PIS!B16 -> 7050.2266 | E24: =PIS!C16 -> 7391.7453 | F24: =PIS!D16 -> 7730.4249 | G24: =PIS!E16 -> 8066.1803 | H24: =PIS!F16 -> 8398.9237
A25: Dividend Payout Ratio | B25: =B23/B24 -> 0.31345277 | C25: =C23/C24 -> 0.40471566 | D25: =D23/D24 -> 0.35 | E25: =E23/E24 -> 0.35 | F25: =F23/F24 -> 0.35 | G25: =G23/G24 -> 0.35 | H25: =H23/H24 -> 0.35
A26: Retention Ratio | B26: =1-B25 -> 0.68654723 | C26: =1-C25 -> 0.59528434 | D26: =1-D25 -> 0.65 | E26: =1-E25 -> 0.65 | F26: =1-F25 -> 0.65 | G26: =1-G25 -> 0.65 | H26: =1-H25 -> 0.65
A27: Equity Capital | B27: ='Historical Data'!E32 -> 288.69 | C27: ='Historical Data'!F32 -> 294.68 | D27: =PBS!B6 -> 294.68 | E27: =PBS!C6 -> 294.68 | F27: =PBS!D6 -> 294.68 | G27: =PBS!E6 -> 294.68 | H27: =PBS!F6 -> 294.68
A28: ROE | B28: =B27/B24 -> 0.044778967 | C28: =C27/C24 -> 0.052221376 | D28: =D27/D24 -> 0.041797238 | E28: =E27/E24 -> 0.039866092 | F28: =F27/F24 -> 0.038119509 | G28: =G27/G24 -> 0.036532781 | H28: =H27/H24 -> 0.035085448
A29: Growth Rate | B29: =B26*B28 -> 0.030742876 | C29: =C26*C28 -> 0.031086567 | D29: =D26*D28 -> 0.027168205 | E29: =E26*E28 -> 0.02591296 | F29: =F26*F28 -> 0.024777681 | G29: =G26*G28 -> 0.023746308 | H29: =H26*H28 -> 0.022805541
H30: =AVERAGE(D29:H29) -> 0.024882139
A32: WORKING FOR WEIGHTED AVERAGE COST OF CAPITAL
A34: Sources of Funds | B34: Market Value | C34: Weight | D34: Cost | E34: Average Weight
A35: Equity | B35: 350000 | C35: =B35/B37 -> 0.93557872 | D35: =B46 -> 0.066736 | E35: =C35*D35 -> 0.062436782
A36: Debt | B36: 24100 | C36: =B36/B37 -> 0.064421278 | D36: =B52 -> 0.051365353 | E36: =C36*D36 -> 0.0033090217
A37: Total | B37: =SUM(B35:B36) -> 374100 | E37: =SUM(E35:E36) -> 0.065745803
A38: WACC | E38: =E37 -> 0.065745803
A40: WORKING FOR COST OF EQUITY
A42: Risk Free Rate of Return | B42: 0.066
A43: Beta | B43: 0.0115
A44: Expected Market Rate of Return | B44: 0.13
A45: Risk Premium | B45: =B44-B42 -> 0.064
A46: Cost of Equity | B46: =B42+B43*B45 -> 0.066736
A48: WORKING FOR COST OF DEBT
A50: Interest | B50: ='Historical Data'!F21 -> 1650.54
A51: Pre Tax Cost of Debt | B51: =B50/B36 -> 0.068487137
...

Sheet Customization
A1: How to use it?
A3: You can customize this workbook as you want.
B4: You can add custom formating, add conditional formating, add your own formulas… do ANYTHING.
B5: Please don't edit the "Data Sheet" only.
A7: After customization, you can upload this back on Screener.
B8: Upload on: | C8: https://www.screener.in/excel/
A10: Download your customized workbooks now onwards.
B11: Now whenever you will "Export to excel" from Screener, it will export your customized file.
A14: TESTING:
B15: This is a testing feature currently.
B16: You can report any formula errors on the worksheet at: support@screener.in
